Workbook

Sheet Initial_Prep
C6: Idea for nudges
C8: Santosh — Work 11:00 AM–8:00 PM
C10: Window | D10: Type | E10: Suggested time | F10: Nudge line
C11: 11:00 AM–1:00 PM | D11: Deep focus | E11: ~12:00 PM | F11: "Know you're heads-down — just a quick one, it's been an hour. Stretch whenever you get a natural gap 🙂"
C12: 1:00 PM–2:00 PM | D12: Free | E12: ~1:45 PM | F12: "Quick stretch or water break before you dive back in?"
C13: 2:00 PM–6:00 PM | D13: Deep focus | E13: ~4:00 PM | F13: "Just flagging — 2 hrs in. No pressure, whenever's a good pause point."
C14: 2:00 PM–6:00 PM | D14: Deep focus | E14: ~6:00 PM | F14: "One more check-in before you wrap this stretch — quick stand-up if you can?"
C15: 6:00 PM–8:00 PM | D15: Free | E15: ~7:00 PM | F15: "Hey — been about an hour again. Quick walk or stretch?"
C16: 6:00 PM–8:00 PM | D16: Free | E16: ~8:00 PM | F16: "Last one for the day — might be a good time to step away for a sec before you log off."
C19: Soumya — Work 9:00 AM–8:30 PM
C21: Window | D21: Type | E21: Suggested time | F21: Nudge line
C22: 9:00 AM–10:00 AM | D22: Free | E22: ~9:45 AM | F22: "Good morning! Quick stretch before you settle into deep work?"
C23: 10:00 AM–2:00 PM | D23: Deep focus | E23: ~12:00 PM | F23: "Know you're focused — just a quick nudge, it's been 2 hrs. Stretch whenever's natural."
C24: 10:00 AM–2:00 PM | D24: Deep focus | E24: ~2:00 PM | F24: "Wrapping up this stretch soon — good time for a proper break before your next block?"
C25: 2:00 PM–4:00 PM | D25: Free | E25: ~3:00 PM | F25: "Quick one — water or a short walk?"
C26: 2:00 PM–4:00 PM | D26: Free | E26: ~4:00 PM | F26: "Hey — before you head into focus mode again, a quick stretch?"
C27: 4:00 PM–7:00 PM | D27: Deep focus | E27: ~5:00 PM | F27: "Just flagging — an hour into this stretch. No pressure, whenever works."
C28: 4:00 PM–7:00 PM | D28: Deep focus | E28: ~7:00 PM | F28: "This has been a long one — worth a proper stand-up break before you close out?"
C29: 7:00 PM–8:30 PM | D29: Free | E29: ~8:00 PM | F29: "Almost done for the day — quick stretch before you log off?"
C33: Archana — Work 9:00 AM–7:00 PM
C35: Window | D35: Type | E35: Suggested time | F35: Nudge line
C36: 9:00 AM–12:00 PM | D36: Deep focus | E36: ~10:00 AM | F36: "Know you're heads-down — just a quick one, it's been an hour. Stretch whenever's natural 🙂"
E37: ~12:10 PM | F37: "Wrapping up this stretch soon — good time for a proper break before you move on?"
C38: 12:00 PM–7:00 PM | D38: Free | E38: ~1:30 PM | F38: "Quick stretch or water break?"
E39: ~3:30 PM | F39: "Hey — been a couple hours, quick one to step away?"
E40: ~5:30 PM | F40: "Afternoon's been long — good time for a proper walk or stretch?"
E41: ~7:00 PM | F41: "Almost done for the day — quick stretch before you log off?"
C43: Karishma — Work 11:00 AM–9:30 PM
C45: Window | D45: Type | E45: Suggested time | F45: Nudge line
C46: 11:00 AM–4:30 PM | D46: Free | E46: ~12:30 PM | F46: "Hey — quick stretch or water before you dive into the afternoon?"
E47: ~2:15 PM | F47: "Been a couple hours — good time to step away for a sec?"
E48: ~4:00 PM | F48: "One more before you head into focus mode — quick walk or stretch?"
C49: 4:30 PM–7:30 PM | D49: Deep focus | E49: ~5:30 PM | F49: "Know you're heads-down — just a quick one, it's been an hour. Stretch whenever's natural 🙂"
E50: ~7:15 PM | F50: "Wrapping up this stretch soon — good time for a proper break before you close it out?"
C51: 7:30 PM–9:30 PM | D51: Free | E51: ~9:00 PM | F51: "Almost done for the day — quick stretch before you log off?"
C54: Vandita — Work 11:00 AM–8:00 PM
C56: Window | D56: Type | E56: Suggested time | F56: Nudge line
C57: 11:00 AM–1:00 PM | D57: Free | E57: ~12:15 PM | F57: "Hey — quick stretch or water before your focus block?"
C58: 1:00 PM–2:00 PM | D58: Deep focus | E58: ~1:45 PM | F58: "Wrapping up soon — good time for a proper break once you're done here?"
C59: 2:00 PM–8:00 PM | D59: Free | E59: ~3:30 PM | F59: "Quick one — water or a short walk?"
...

Sheet Nudge Log
A1: Date | B1: Name | C1: Focused work time | D1: Start work Time | E1: End work time | F1: Nudge (1/2/3/4) | G1: Nudge time | H1: Acted (Y/N) | I1: Note (If missed, why)
A2: 46266 | B2: Archana | C2: 9-12 pm | D2: 0.375 | E2: 0.79166667 | F2: 1 | G2: 0.43125 | H2: Y
A3: 46266 | B3: Sushant | C3: 2:30-5:00 pm , 6-8:30 pm | D3: 0.54166667 | E3: 0.9375 | F3: 1 | G3: 0.59236111 | H3: Y | I3: Resent at 2:31 PM ("Done?"); he reacted 👍 at 2:32 PM
A4: 46266 | B4: Vandita | C4: 1-2 pm , 8 pm | D4: 0.45833333 | E4: 0.83333333 | F4: 1 | G4: 0.50972222 | H4: Y
A5: 46266 | B5: Santosh | C5: 11am-1 pm , 2-6 pm | D5: 0.45833333 | E5: 0.83333333 | F5: 1 | G5: 0.50416667 | H5: Y
A6: 46266 | B6: Soumya | C6: 10am-2 pm , 4-7 pm | D6: 0.375 | E6: 0.85416667 | F6: 1 | G6: 0.43055556 | H6: Y
A7: 46266 | B7: Karishma | C7: 4:30-7:30 Pm | D7: 0.45833333 | E7: 0.89583333 | F7: 1 | G7: 0.51111111 | H7: N | I7: "I have back to back calls till 1pm" , did follow up at 1:05 pm
A8: 46266 | B8: Archana | C8: 9-12 pm | D8: 0.375 | E8: 0.79166667 | F8: 2 | G8: 0.56111111 | H8: N
A9: 46266 | B9: Sushant | C9: 2:30-5:00 pm , 6-8:30 pm | D9: 0.54166667 | E9: 0.9375 | F9: 2 | G9: 0.65 | H9: Y
A10: 46266 | B10: Vandita | C10: 1-2 pm , 8 pm | D10: 0.45833333 | E10: 0.83333333 | F10: 2 | G10: 0.56805556 | H10: Y
A11: 46266 | B11: Santosh | C11: 11am-1 pm , 2-6 pm | D11: 0.45833333 | E11: 0.83333333 | F11: 2 | G11: 0.56944444 | H11: Y
A12: 46266 | B12: Soumya | C12: 10am-2 pm , 4-7 pm | D12: 0.375 | E12: 0.85416667 | F12: 2 | G12: 0.52361111 | H12: Y
A13: 46266 | B13: Karishma | C13: 4:30-7:30 Pm | D13: 0.45833333 | E13: 0.89583333 | F13: 2 | G13: 0.54513889 | H13: N | I13: Confirmed later (2:48 PM) — "No I was continuously sitting on a call"
A14: 46266 | B14: Archana | C14: 9-12 pm | D14: 0.375 | E14: 0.79166667 | F14: 3 | G14: 0.65416667 | H14: N
A15: 46266 | B15: Sushant | C15: 2:30-5:00 pm , 6-8:30 pm | D15: 0.54166667 | E15: 0.9375 | F15: 3 | G15: 0.71111111 | H15: Y | I15: Replied "Having snaks" at 5:19 PM
A16: 46266 | B16: Vandita | C16: 1-2 pm , 8 pm | D16: 0.45833333 | E16: 0.83333333 | F16: 3 | G16: 0.64930556 | H16: Y | I16: Replied "Water"
A17: 46266 | B17: Santosh | C17: 11am-1 pm , 2-6 pm | D17: 0.45833333 | E17: 0.83333333 | F17: 3 | G17: 0.65138889 | H17: Y
A18: 46266 | B18: Soumya | C18: 10am-2 pm , 4-7 pm | D18: 0.375 | E18: 0.85416667 | F18: 3 | G18: 0.60069444 | H18: Y
A19: 46266 | B19: Karishma | C19: 4:30-7:30 Pm | D19: 0.45833333 | E19: 0.89583333 | F19: 3 | G19: 0.59791667 | H19: Y | I19: Replied 2:22 PM — "I just took a break for lunch" (self-initiated, coincided with nudge)
A20: 46266 | B20: Archana | C20: 9-12 pm | D20: 0.375 | E20: 0.79166667 | F20: 4 | G20: 0.7375 | H20: N
A21: 46266 | B21: Sushant | C21: 2:30-5:00 pm , 6-8:30 pm | D21: 0.54166667 | E21: 0.9375 | F21: 4 | G21: 0.75833333 | H21: Y | I21: Initially replied "No" at 9:02 PM, then "Now going for this" + "And a small break" at 9:03 PM — acted late, after prompting
A22: 46266 | B22: Vandita | C22: 1-2 pm , 8 pm | D22: 0.45833333 | E22: 0.83333333 | F22: 4 | G22: 0.73680556 | H22: N | I22: No response at the time — addressed later (7:24 PM catch-up), said "nothing forced me to miss," but prefers to self-decide breaks rather than wait for a prompt
A23: 46266 | B23: Santosh | C23: 11am-1 pm , 2-6 pm | D23: 0.45833333 | E23: 0.83333333 | F23: 4 | G23: 0.75208333 | H23: Y
A24: 46266 | B24: Soumya | C24: 10am-2 pm , 4-7 pm | D24: 0.375 | E24: 0.85416667 | F24: 4 | G24: 0.66736111 | H24: N | I24: Said "No" — declined the break
A25: 46266 | B25: Karishma | C25: 4:30-7:30 Pm | D25: 0.45833333 | E25: 0.89583333 | F25: 4 | G25: 0.66875 | H25: Y | I25: Replied "Done" at 4:15 PM
A26: 46266 | B26: Archana | C26: 9-12 pm | D26: 0.375 | E26: 0.79166667 | F26: 5 | G26: 0.88055556 | H26: N
A27: 46266 | B27: Sushant | C27: 2:30-5:00 pm , 6-8:30 pm | D27: 0.54166667 | E27: 0.9375 | F27: 5 | G27: 0.86041667 | H27: Y | I27: Bundled into the 8:56 PM check-in; likely covered by his 9:03 PM "Now going for this" reply, but not explicitly confirmed separately from Nudge 4
A28: 46266 | B28: Vandita | C28: 1-2 pm , 8 pm | D28: 0.45833333 | E28: 0.83333333 | F28: 5 | G28: 0.80833333 | H28: Y | I28: No explicit confirmation of action; she gave general feedback instead
A29: 46266 | B29: Santosh | C29: 11am-1 pm , 2-6 pm | D29: 0.45833333 | E29: 0.83333333 | F29: 5 | G29: 0.85833333 | H29: Y
A30: 46266 | B30: Soumya | C30: 10am-2 pm , 4-7 pm | D30: 0.375 | E30: 0.85416667 | F30: 5 | G30: 0.72569444 | H30: Y
A31: 46266 | B31: Karishma | C31: 4:30-7:30 Pm | D31: 0.45833333 | E31: 0.89583333 | F31: 5 | G31: 0.73611111 | H31: Y | I31: Replied "Done" at 6:01 PM
A32: 46266 | B32: Sushant | C32: 2:30-5:00 pm , 6-8:30 pm | D32: 0.54166667 | E32: 0.9375 | F32: 6 | G32: 0.94166667 | H32: Y | I32: Came down for the cab by walking .
A33: 46266 | B33: Santosh | C33: 11am-1 pm , 2-6 pm | D33: 0.45833333 | E33: 0.83333333 | F33: 6 | G33: 0.85833333 | H33: Y
A34: 46266 | B34: Soumya | C34: 10am-2 pm , 4-7 pm | D34: 0.375 | E34: 0.85416667 | F34: 6 | G34: 0.85833333 | H34: Y | I34: Logging off in 5 min
A35: 46266 | B35: Karishma | C35: 4:30-7:30 Pm | D35: 0.45833333 | E35: 0.89583333 | F35: 6 | G35: 0.85972222 | H35: N | I35: Sent, no reply yet — logout nudge
A36: 46267 | B36: Archana | C36: 9-12 pm | D36: 0.375 | E36: 0.79166667 | F36: 1 | G36: 0.42916667 | H36: N
A37: 46267 | B37: Sushant | C37: 2:30-5:00 pm , 6-8:30 pm | D37: 0.54166667 | E37: 0.9375 | F37: 1 | G37: 0.56041667 | H37: Y
A38: 46267 | B38: Vandita | C38: 1-2 pm , 8 pm | D38: 0.45833333 | E38: 0.83333333 | F38: 1 | G38: 0.50555556 | H38: N
A39: 46267 | B39: Santosh | C39: 11am-1 pm , 2-6 pm | D39: 0.45833333 | E39: 0.83333333 | F39: 1 | G39: 0.50555556 | H39: Y
A40: 46267 | B40: Soumya | C40: 10am-2 pm , 4-7 pm | D40: 0.375 | E40: 0.85416667 | F40: 1 | G40: 0.41805556 | H40: N | I40: Replied No
...

Sheet Daily Summary
A1: Date | B1: Name | C1: Nudges Sent | D1: Nudges Acted On | E1: % Acted On | F1: Comments
A2: 46266 | B2: Archana | C2: =IF(OR(A2="",B2=""),"",COUNTIFS('Nudge Log'!$A$3:$A$193,A2,'Nudge Log'!$B$3:$B$193,B2)) -> 4 | D2: 1 | E2: =IF(OR(C2="",C2=0),"",D2/C2) -> 0.25
A3: 46266 | B3: Sushant | C3: =IF(OR(A3="",B3=""),"",COUNTIFS('Nudge Log'!$A$3:$A$193,A3,'Nudge Log'!$B$3:$B$193,B3)) -> 6 | D3: =IF(OR(A3="",B3=""),"",COUNTIFS('Nudge Log'!$A$3:$A$193,A3,'Nudge Log'!$B$3:$B$193,B3,'Nudge Log'!$H$3:$H$193,"Y")) -> 6 | E3: =IF(OR(C3="",C3=0),"",D3/C3) -> 1
A4: 46266 | B4: Vandita | C4: =IF(OR(A4="",B4=""),"",COUNTIFS('Nudge Log'!$A$3:$A$193,A4,'Nudge Log'!$B$3:$B$193,B4)) -> 5 | D4: =IF(OR(A4="",B4=""),"",COUNTIFS('Nudge Log'!$A$3:$A$193,A4,'Nudge Log'!$B$3:$B$193,B4,'Nudge Log'!$H$3:$H$193,"Y")) -> 4 | E4: =IF(OR(C4="",C4=0),"",D4/C4) -> 0.8
A5: 46266 | B5: Santosh | C5: =IF(OR(A5="",B5=""),"",COUNTIFS('Nudge Log'!$A$3:$A$193,A5,'Nudge Log'!$B$3:$B$193,B5)) -> 6 | D5: =IF(OR(A5="",B5=""),"",COUNTIFS('Nudge Log'!$A$3:$A$193,A5,'Nudge Log'!$B$3:$B$193,B5,'Nudge Log'!$H$3:$H$193,"Y")) -> 6 | E5: =IF(OR(C5="",C5=0),"",D5/C5) -> 1
A6: 46266 | B6: Soumya | C6: =IF(OR(A6="",B6=""),"",COUNTIFS('Nudge Log'!$A$3:$A$193,A6,'Nudge Log'!$B$3:$B$193,B6)) -> 6 | D6: =IF(OR(A6="",B6=""),"",COUNTIFS('Nudge Log'!$A$3:$A$193,A6,'Nudge Log'!$B$3:$B$193,B6,'Nudge Log'!$H$3:$H$193,"Y")) -> 5 | E6: =IF(OR(C6="",C6=0),"",D6/C6) -> 0.83333333
A7: 46266 | B7: Karishma | C7: =IF(OR(A7="",B7=""),"",COUNTIFS('Nudge Log'!$A$3:$A$193,A7,'Nudge Log'!$B$3:$B$193,B7)) -> 6 | D7: =IF(OR(A7="",B7=""),"",COUNTIFS('Nudge Log'!$A$3:$A$193,A7,'Nudge Log'!$B$3:$B$193,B7,'Nudge Log'!$H$3:$H$193,"Y")) -> 3 | E7: =IF(OR(C7="",C7=0),"",D7/C7) -> 0.5
A8: 46267 | B8: Archana | C8: 6 | D8: 2 | E8: =IF(OR(C8="",C8=0),"",D8/C8) -> 0.33333333 | F8: Busy with release Work
A9: 46267 | B9: Sushant | C9: =IF(OR(A8="",B9=""),"",COUNTIFS('Nudge Log'!$A$3:$A$193,A8,'Nudge Log'!$B$3:$B$193,B9)) -> 6 | D9: =IF(OR(A8="",B9=""),"",COUNTIFS('Nudge Log'!$A$3:$A$193,A8,'Nudge Log'!$B$3:$B$193,B9,'Nudge Log'!$H$3:$H$193,"Y")) -> 5 | E9: =IF(OR(C9="",C9=0),"",D9/C9) -> 0.83333333
A10: 46267 | B10: Vandita | C10: =IF(OR(A10="",B10=""),"",COUNTIFS('Nudge Log'!$A$3:$A$193,A10,'Nudge Log'!$B$3:$B$193,B10)) -> 5 | D10: =IF(OR(A10="",B10=""),"",COUNTIFS('Nudge Log'!$A$3:$A$193,A10,'Nudge Log'!$B$3:$B$193,B10,'Nudge Log'!$H$3:$H$193,"Y")) -> 2 | E10: =IF(OR(C10="",C10=0),"",D10/C10) -> 0.4
A11: 46267 | B11: Santosh | C11: =IF(OR(A11="",B11=""),"",COUNTIFS('Nudge Log'!$A$3:$A$193,A11,'Nudge Log'!$B$3:$B$193,B11)) -> 5 | D11: =IF(OR(A11="",B11=""),"",COUNTIFS('Nudge Log'!$A$3:$A$193,A11,'Nudge Log'!$B$3:$B$193,B11,'Nudge Log'!$H$3:$H$193,"Y")) -> 5 | E11: =IF(OR(C11="",C11=0),"",D11/C11) -> 1
A12: 46267 | B12: Soumya | C12: =IF(OR(A12="",B12=""),"",COUNTIFS('Nudge Log'!$A$3:$A$193,A12,'Nudge Log'!$B$3:$B$193,B12)) -> 5 | D12: =IF(OR(A12="",B12=""),"",COUNTIFS('Nudge Log'!$A$3:$A$193,A12,'Nudge Log'!$B$3:$B$193,B12,'Nudge Log'!$H$3:$H$193,"Y")) -> 3 | E12: =IF(OR(C12="",C12=0),"",D12/C12) -> 0.6
A13: 46267 | B13: Karishma | C13: =IF(OR(A13="",B13=""),"",COUNTIFS('Nudge Log'!$A$3:$A$193,A13,'Nudge Log'!$B$3:$B$193,B13)) -> 5 | D13: =IF(OR(A13="",B13=""),"",COUNTIFS('Nudge Log'!$A$3:$A$193,A13,'Nudge Log'!$B$3:$B$193,B13,'Nudge Log'!$H$3:$H$193,"Y")) -> 5 | E13: =IF(OR(C13="",C13=0),"",D13/C13) -> 1
A14: 46268 | B14: Archana | C14: =IF(OR(A14="",B14=""),"",COUNTIFS('Nudge Log'!$A$3:$A$193,A14,'Nudge Log'!$B$3:$B$193,B14)) -> 6 | D14: =IF(OR(A14="",B14=""),"",COUNTIFS('Nudge Log'!$A$3:$A$193,A14,'Nudge Log'!$B$3:$B$193,B14,'Nudge Log'!$H$3:$H$193,"Y")) -> 0 | E14: =IF(OR(C14="",C14=0),"",D14/C14) -> 0 | F14: Busy with release Work
A15: 46268 | B15: Sushant | C15: =IF(OR(A15="",B15=""),"",COUNTIFS('Nudge Log'!$A$3:$A$193,A15,'Nudge Log'!$B$3:$B$193,B15)) -> 6 | D15: =IF(OR(A15="",B15=""),"",COUNTIFS('Nudge Log'!$A$3:$A$193,A15,'Nudge Log'!$B$3:$B$193,B15,'Nudge Log'!$H$3:$H$193,"Y")) -> 3 | E15: =IF(OR(C15="",C15=0),"",D15/C15) -> 0.5
A16: 46268 | B16: Vandita | C16: =IF(OR(A16="",B16=""),"",COUNTIFS('Nudge Log'!$A$3:$A$193,A16,'Nudge Log'!$B$3:$B$193,B16)) -> 5 | D16: =IF(OR(A16="",B16=""),"",COUNTIFS('Nudge Log'!$A$3:$A$193,A16,'Nudge Log'!$B$3:$B$193,B16,'Nudge Log'!$H$3:$H$193,"Y")) -> 0 | E16: =IF(OR(C16="",C16=0),"",D16/C16) -> 0 | F16: No Reply
A17: 46268 | B17: Santosh | C17: =IF(OR(A17="",B17=""),"",COUNTIFS('Nudge Log'!$A$3:$A$193,A17,'Nudge Log'!$B$3:$B$193,B17)) -> 4 | D17: =IF(OR(A17="",B17=""),"",COUNTIFS('Nudge Log'!$A$3:$A$193,A17,'Nudge Log'!$B$3:$B$193,B17,'Nudge Log'!$H$3:$H$193,"Y")) -> 4 | E17: =IF(OR(C17="",C17=0),"",D17/C17) -> 1
A18: 46268 | B18: Soumya | C18: =IF(OR(A18="",B18=""),"",COUNTIFS('Nudge Log'!$A$3:$A$193,A18,'Nudge Log'!$B$3:$B$193,B18)) -> 6 | D18: =IF(OR(A18="",B18=""),"",COUNTIFS('Nudge Log'!$A$3:$A$193,A18,'Nudge Log'!$B$3:$B$193,B18,'Nudge Log'!$H$3:$H$193,"Y")) -> 5 | E18: =IF(OR(C18="",C18=0),"",D18/C18) -> 0.83333333
A19: 46268 | B19: Karishma | C19: =IF(OR(A19="",B19=""),"",COUNTIFS('Nudge Log'!$A$3:$A$193,A19,'Nudge Log'!$B$3:$B$193,B19)) -> 6 | D19: =IF(OR(A19="",B19=""),"",COUNTIFS('Nudge Log'!$A$3:$A$193,A19,'Nudge Log'!$B$3:$B$193,B19,'Nudge Log'!$H$3:$H$193,"Y")) -> 0 | E19: =IF(OR(C19="",C19=0),"",D19/C19) -> 0 | F19: Replied had a very busy day so couldn't follow the nudges
A20: 46269 | B20: Archana | C20: =IF(OR(A20="",B20=""),"",COUNTIFS('Nudge Log'!$A$3:$A$193,A20,'Nudge Log'!$B$3:$B$193,B20)) -> 5 | D20: =IF(OR(A20="",B20=""),"",COUNTIFS('Nudge Log'!$A$3:$A$193,A20,'Nudge Log'!$B$3:$B$193,B20,'Nudge Log'!$H$3:$H$193,"Y")) -> 1 | E20: =IF(OR(C20="",C20=0),"",D20/C20) -> 0.2 | F20: Busy with release Work
A21: 46269 | B21: Sushant | C21: =IF(OR(A21="",B21=""),"",COUNTIFS('Nudge Log'!$A$3:$A$193,A21,'Nudge Log'!$B$3:$B$193,B21)) -> 4 | D21: =IF(OR(A21="",B21=""),"",COUNTIFS('Nudge Log'!$A$3:$A$193,A21,'Nudge Log'!$B$3:$B$193,B21,'Nudge Log'!$H$3:$H$193,"Y")) -> 4 | E21: =IF(OR(C21="",C21=0),"",D21/C21) -> 1
A22: 46269 | B22: Vandita | C22: =IF(OR(A22="",B22=""),"",COUNTIFS('Nudge Log'!$A$3:$A$193,A22,'Nudge Log'!$B$3:$B$193,B22)) -> 2 | D22: =IF(OR(A22="",B22=""),"",COUNTIFS('Nudge Log'!$A$3:$A$193,A22,'Nudge Log'!$B$3:$B$193,B22,'Nudge Log'!$H$3:$H$193,"Y")) -> 0 | E22: =IF(OR(C22="",C22=0),"",D22/C22) -> 0 | F22: No Reply
A23: 46269 | B23: Santosh | C23: =IF(OR(A23="",B23=""),"",COUNTIFS('Nudge Log'!$A$3:$A$193,A23,'Nudge Log'!$B$3:$B$193,B23)) -> 5 | D23: =IF(OR(A23="",B23=""),"",COUNTIFS('Nudge Log'!$A$3:$A$193,A23,'Nudge Log'!$B$3:$B$193,B23,'Nudge Log'!$H$3:$H$193,"Y")) -> 4 | E23: =IF(OR(C23="",C23=0),"",D23/C23) -> 0.8
A24: 46269 | B24: Soumya | C24: =IF(OR(A24="",B24=""),"",COUNTIFS('Nudge Log'!$A$3:$A$193,A24,'Nudge Log'!$B$3:$B$193,B24)) -> 4 | D24: =IF(OR(A24="",B24=""),"",COUNTIFS('Nudge Log'!$A$3:$A$193,A24,'Nudge Log'!$B$3:$B$193,B24,'Nudge Log'!$H$3:$H$193,"Y")) -> 4 | E24: =IF(OR(C24="",C24=0),"",D24/C24) -> 1
A25: 46269 | B25: Karishma | C25: =IF(OR(A25="",B25=""),"",COUNTIFS('Nudge Log'!$A$3:$A$193,A25,'Nudge Log'!$B$3:$B$193,B25)) -> 5 | D25: =IF(OR(A25="",B25=""),"",COUNTIFS('Nudge Log'!$A$3:$A$193,A25,'Nudge Log'!$B$3:$B$193,B25,'Nudge Log'!$H$3:$H$193,"Y")) -> 2 | E25: =IF(OR(C25="",C25=0),"",D25/C25) -> 0.4 | F25: Replied Sorry I m extremely busy with lots of things around and festival
C26: =IF(OR(A26="",B26=""),"",COUNTIFS('Nudge Log'!$A$3:$A$193,A26,'Nudge Log'!$B$3:$B$193,B26)) | D26: =IF(OR(A26="",B26=""),"",COUNTIFS('Nudge Log'!$A$3:$A$193,A26,'Nudge Log'!$B$3:$B$193,B26,'Nudge Log'!$H$3:$H$193,"Y")) | E26: =IF(OR(C26="",C26=0),"",D26/C26)
C27: =IF(OR(A27="",B27=""),"",COUNTIFS('Nudge Log'!$A$3:$A$193,A27,'Nudge Log'!$B$3:$B$193,B27)) | D27: =IF(OR(A27="",B27=""),"",COUNTIFS('Nudge Log'!$A$3:$A$193,A27,'Nudge Log'!$B$3:$B$193,B27,'Nudge Log'!$H$3:$H$193,"Y")) | E27: =IF(OR(C27="",C27=0),"",D27/C27)
C28: =IF(OR(A28="",B28=""),"",COUNTIFS('Nudge Log'!$A$3:$A$193,A28,'Nudge Log'!$B$3:$B$193,B28)) | D28: =IF(OR(A28="",B28=""),"",COUNTIFS('Nudge Log'!$A$3:$A$193,A28,'Nudge Log'!$B$3:$B$193,B28,'Nudge Log'!$H$3:$H$193,"Y")) | E28: =IF(OR(C28="",C28=0),"",D28/C28)
C29: =IF(OR(A29="",B29=""),"",COUNTIFS('Nudge Log'!$A$3:$A$193,A29,'Nudge Log'!$B$3:$B$193,B29)) | D29: =IF(OR(A29="",B29=""),"",COUNTIFS('Nudge Log'!$A$3:$A$193,A29,'Nudge Log'!$B$3:$B$193,B29,'Nudge Log'!$H$3:$H$193,"Y")) | E29: =IF(OR(C29="",C29=0),"",D29/C29)
C30: =IF(OR(A30="",B30=""),"",COUNTIFS('Nudge Log'!$A$3:$A$193,A30,'Nudge Log'!$B$3:$B$193,B30)) | D30: =IF(OR(A30="",B30=""),"",COUNTIFS('Nudge Log'!$A$3:$A$193,A30,'Nudge Log'!$B$3:$B$193,B30,'Nudge Log'!$H$3:$H$193,"Y")) | E30: =IF(OR(C30="",C30=0),"",D30/C30)
C31: =IF(OR(A31="",B31=""),"",COUNTIFS('Nudge Log'!$A$3:$A$193,A31,'Nudge Log'!$B$3:$B$193,B31)) | D31: =IF(OR(A31="",B31=""),"",COUNTIFS('Nudge Log'!$A$3:$A$193,A31,'Nudge Log'!$B$3:$B$193,B31,'Nudge Log'!$H$3:$H$193,"Y")) | E31: =IF(OR(C31="",C31=0),"",D31/C31)
C32: =IF(OR(A32="",B32=""),"",COUNTIFS('Nudge Log'!$A$3:$A$193,A32,'Nudge Log'!$B$3:$B$193,B32)) | D32: =IF(OR(A32="",B32=""),"",COUNTIFS('Nudge Log'!$A$3:$A$193,A32,'Nudge Log'!$B$3:$B$193,B32,'Nudge Log'!$H$3:$H$193,"Y")) | E32: =IF(OR(C32="",C32=0),"",D32/C32)
C33: =IF(OR(A33="",B33=""),"",COUNTIFS('Nudge Log'!$A$3:$A$193,A33,'Nudge Log'!$B$3:$B$193,B33)) | D33: =IF(OR(A33="",B33=""),"",COUNTIFS('Nudge Log'!$A$3:$A$193,A33,'Nudge Log'!$B$3:$B$193,B33,'Nudge Log'!$H$3:$H$193,"Y")) | E33: =IF(OR(C33="",C33=0),"",D33/C33)
C34: =IF(OR(A34="",B34=""),"",COUNTIFS('Nudge Log'!$A$3:$A$193,A34,'Nudge Log'!$B$3:$B$193,B34)) | D34: =IF(OR(A34="",B34=""),"",COUNTIFS('Nudge Log'!$A$3:$A$193,A34,'Nudge Log'!$B$3:$B$193,B34,'Nudge Log'!$H$3:$H$193,"Y")) | E34: =IF(OR(C34="",C34=0),"",D34/C34)
C35: =IF(OR(A35="",B35=""),"",COUNTIFS('Nudge Log'!$A$3:$A$193,A35,'Nudge Log'!$B$3:$B$193,B35)) | D35: =IF(OR(A35="",B35=""),"",COUNTIFS('Nudge Log'!$A$3:$A$193,A35,'Nudge Log'!$B$3:$B$193,B35,'Nudge Log'!$H$3:$H$193,"Y")) | E35: =IF(OR(C35="",C35=0),"",D35/C35)
C36: =IF(OR(A36="",B36=""),"",COUNTIFS('Nudge Log'!$A$3:$A$193,A36,'Nudge Log'!$B$3:$B$193,B36)) | D36: =IF(OR(A36="",B36=""),"",COUNTIFS('Nudge Log'!$A$3:$A$193,A36,'Nudge Log'!$B$3:$B$193,B36,'Nudge Log'!$H$3:$H$193,"Y")) | E36: =IF(OR(C36="",C36=0),"",D36/C36)
C37: =IF(OR(A37="",B37=""),"",COUNTIFS('Nudge Log'!$A$3:$A$193,A37,'Nudge Log'!$B$3:$B$193,B37)) | D37: =IF(OR(A37="",B37=""),"",COUNTIFS('Nudge Log'!$A$3:$A$193,A37,'Nudge Log'!$B$3:$B$193,B37,'Nudge Log'!$H$3:$H$193,"Y")) | E37: =IF(OR(C37="",C37=0),"",D37/C37)
... C41: =IF(OR(A41="",B41=""),"",COUNTIFS('Nudge Log'!$A$3:$A$193,A41,'Nudge Log'!$B$3:$B$193,B41)) | D41: =IF(OR(A41="",B41=""),"",COUNTIFS('Nudge Log'!$A$3:$A$193,A41,'Nudge Log'!$B$3:$B$193,B41,'Nudge Log'!$H$3:$H$193,"Y")) | E41: =IF(OR(C41="",C41=0),"",D41/C41)

Sheet Feedback summary
A1: Name | B1: Still responding by last day? (Y/N) | C1: Be honest — by today, were you still reading/acting on my nudges, or had you started tuning them out? | D1: Did this change anything about how often you actually got up or took breaks, compared to a normal week? | E1: Did it ever feel naggy or like I was checking up on you, or did it feel more like a helpful heads-up? | F1: If this were an automatic app instead of me texting you, would you actually want it? Why or why not? | G1: Out of 5, how useful was this overall? | H1: Comments
A2: Archana | B2: Y | C2: Yes I did check notifications | D2: Yes. This was helpful | E2: No (For Naggy) | F2: Yes. The only thing is the phone should be around. I sometimes keep my phone away unconsciously | G2: 5
A3: Sushant | B3: Y | C3: Still reading nudges | D3: A little change. Mostly acting on notification of drinking water and taking walk. | E3: Mostly it is fine. It doesnot disturb as of now. | F3: May be yes but not in weekends. | G3: 4
A4: Vandita | B4: N
A5: Santosh | B5: Y | C5: I was still reading it but not with the same interest. I did some time but not every time as I was busy . | D5: Not much changes but these were good reminders to look at your self care being at work (it's just 4 days) | E5: Not naggy but sometimes feels annoying when you are super busy | F5: It would be better if it is in the app | G5: 3.5 | H5: Overall these were the good reminders and did help during the times I was not very occupied.
A6: Soumya | B6: Y | C6: I started to tuning them like why no much nudges today | D6: Yes, i usually did not take break for every 1 or 2 hours in deep focus time | E6: Feel too many nudges in deep focus time would be naggy as our concentration will be distracted Also just a suggestion usually when our eyes feel strain we normally look out somewhere outside or just getup or change the sitting position | F6: May be yes if we are really worried about health or any major health issues we keep alarm on frequent intervals or to remind something like tablets or meetings in that perspective automatic app should be helpful | G6: 3.5
A7: Karishma | B7: Y | C7: Yes, I was still reading and acting on your nudges. They were a good reminder and helped me stay mindful about taking breaks. | D7: Yes, definitely. I found myself getting up and taking short breaks more often than I normally would, so it did make a difference to my routine. | E7: Not at all. It felt more like a helpful heads-up rather than being naggy or like someone was checking up on me. The timing and tone made it easy to follow. | F7: Yes, I would definitely consider using it as an automatic app. Having timely reminders throughout the day would be useful, especially when I’m focused on work and lose track of time. | G7: 5 | H7: The key would be keeping the reminders simple and not too frequent.

Sheet Chat-Verified Nudge Log
A1: Date | B1: Name | C1: Nudge Time | D1: Nudge Given (summary) | E1: Reply Time | F1: Reply Text | G1: Action Done (Y/N/Unclear) | H1: Notes | J1: How this tab was built
A2: 01-Sep-2026 | B2: Archana | C2: 10:21 AM | D2: Know you're heads-down - stretch, ~1hr in | E2: 10:21 AM | F2: 👍 | G2: Y | J2: Built directly from the raw WhatsApp chat exports for all 6 participants (Day 0-4), not from the earlier planned schedule.
A3: 01-Sep-2026 | B3: Archana | C3: 1:28 PM | D3: Quick walk/water/eye relax (look at distant object) | E3: - | F3: - | G3: Unclear | H3: Batch-confirmed later: only 2 of nudges 2-6 followed, unspecified which (see 9:42 PM note) | J3: One row = one distinct nudge sent. Reply time/text is the participant's actual response where one exists.
A4: 01-Sep-2026 | B4: Archana | C4: 3:42 PM | D4: Check on prior + couple hrs, quick break to step away | E4: - | F4: - | G4: Unclear | H4: Same batch note as above | J4: "Y" = confirmed done (explicit reply, emoji, or batch end-of-day confirmation). "N" = confirmed missed or no reply logged. "Unclear" = a batch reply covered only some of a block of nudges without specifying which ones.
A5: 01-Sep-2026 | B5: Archana | C5: 4:39 PM | D5: Quick check - 👍 if managed either of last two | E5: - | F5: - | G5: Unclear | H5: Same batch note as above | J5: Where a person confirmed multiple nudges in one batched message (e.g. "replied with thumbs up for all the nudges"), each underlying nudge is still listed as its own row, with the batch quote repeated in Notes so the source is traceable.
A6: 01-Sep-2026 | B6: Archana | C6: 5:42 PM | D6: Afternoon's been long - proper walk or stretch | E6: - | F6: - | G6: Unclear | H6: Same batch note as above
A7: 01-Sep-2026 | B7: Archana | C7: 9:08 PM | D7: Almost done for day - quick stretch before logoff | E7: 9:42 PM | F7: (Followed two nudges and replied with 👍) | G7: Unclear | H7: Batch ack covers 2 of nudges 2-6; she did not specify which two
A8: 02-Sep-2026 | B8: Archana | C8: 10:18 AM | D8: Hour in - stretch or eye break | E8: - | F8: - | G8: Unclear | H8: Batch-confirmed: only 2 of the 6 Day-2 nudges followed, unspecified which
A9: 02-Sep-2026 | B9: Archana | C9: 12:05 PM | D9: Focus block wrapping up - proper pause, stretch/walk | E9: - | F9: - | G9: Unclear | H9: Same batch note
A10: 02-Sep-2026 | B10: Archana | C10: 1:54 PM | D10: Hope in sync - water, walk, or look away | E10: - | F10: - | G10: Unclear | H10: Same batch note
A11: 02-Sep-2026 | B11: Archana | C11: 3:30 PM | D11: Couple hrs hooked - seated stretches (neck rolls etc.) | E11: - | F11: - | G11: Unclear | H11: Same batch note
A12: 02-Sep-2026 | B12: Archana | C12: 5:42 PM | D12: Long time no see - reset, stretch or short walk | E12: - | F12: - | G12: Unclear | H12: Same batch note
A13: 02-Sep-2026 | B13: Archana | C13: 7:34 PM | D13: Almost logout - one last stretch | E13: - | F13: (Followed two nudges and replied with 👍) | G13: Unclear | H13: Batch ack covers 2 of 6; unspecified which
A14: 03-Sep-2026 | B14: Archana | C14: 10:31 AM | D14: More than an hour - unfold, stretch or walk | E14: - | F14: - | G14: N | H14: "No response received for any nudges" (explicit, confirmed by her silence to direct ask at 9:22 PM)
A15: 03-Sep-2026 | B15: Archana | C15: 12:27 PM | D15: Focus block's done - move with small break | E15: - | F15: - | G15: N | H15: Same
A16: 03-Sep-2026 | B16: Archana | C16: 1:33 PM | D16: Screen break - your eyes will thank you | E16: - | F16: - | G16: N | H16: Same
A17: 03-Sep-2026 | B17: Archana | C17: 3:33 PM | D17: Couple hrs hooked - seated stretches | E17: - | F17: - | G17: N | H17: Same
... A20: 04-Sep-2026 | B20: Archana | C20: 12:09 PM | D20: Focus block's done - move with small break | E20: - | F20: - | G20: N | H20: She cited Day-4 release workload at 12:05 PM before this; no further replies logged
A21: 04-Sep-2026 | B21: Archana | C21: 1:41 PM | D21: Screen break for sometime | E21: - | F21: - | G21: N
A22: 04-Sep-2026 | B22: Archana | C22: 3:01 PM | D22: Couple hrs hooked - seated stretches | E22: - | F22: - | G22: N
A23: 04-Sep-2026 | B23: Archana | C23: 4:42 PM | D23: Quite a while in ofc tasks - quick move or water | E23: - | F23: - | G23: N
A24: 04-Sep-2026 | B24: Archana | C24: 7:08 PM | D24: Busy day - nearly done, one last stretch | E24: - | F24: - | G24: N | H24: Feedback questions sent after; reply pending at time of this log
A25: 01-Sep-2026 | B25: Karishma | C25: 12:16 PM | D25: Quick stretch or water/tea/coffee before afternoon | E25: 12:16 PM | F25: "I have back to back calls till 1pm" | G25: N | H25: Blocked by calls
A26: 01-Sep-2026 | B26: Karishma | C26: 1:05 PM | D26: Calls done? Good time for stretch/water/coffee (catch-up) | E26: 2:48 PM | F26: "No I was continuously sitting on a call" | G26: N | H26: Confirmed missed after a delayed follow-up exchange
A27: 01-Sep-2026 | B27: Karishma | C27: 2:21 PM | D27: Also: glued to system a while - step away for a bit? | E27: 2:22 PM / 2:47 PM | F27: "I just took a break for lunch" / "Yes" | G27: Y | H27: Self-initiated lunch break coincided with this nudge
A28: 01-Sep-2026 | B28: Karishma | C28: 4:03 PM | D28: One before focus mode - quick walk or water/coffee | E28: 4:15 PM | F28: "Done" | G28: Y
A29: 01-Sep-2026 | B29: Karishma | C29: 5:40 PM | D29: Know you're heads-down, ~hour in - stretch whenever natural | E29: 6:01 PM | F29: "Done" | G29: Y
A30: 01-Sep-2026 | B30: Karishma | C30: 8:38 PM | D30: Almost done for day - quick stretch before logoff | E30: - | F30: - | G30: N | H30: No reply logged
A31: 02-Sep-2026 | B31: Karishma | C31: 12:18 PM | D31: Quick stretch/water before afternoon (+ seated-stretch note added for calls) | E31: 12:59 PM | F31: "Done" | G31: Y | H31: First day the seated/on-call stretch fallback was introduced
A32: 02-Sep-2026 | B32: Karishma | C32: 1:56 PM | D32: Been a bit - good time to step away for a moment? | E32: 2:58 PM | F32: "Took a break for lunch" | G32: Y
A33: 02-Sep-2026 | B33: Karishma | C33: 2:59 PM | D33: Don't forget short walk after lunch before starting work | E33: 3:24 PM | F33: "Done" | G33: Y
A34: 02-Sep-2026 | B34: Karishma | C34: 5:34 PM | D34: Deep focus mode on - tiny pause, green tea break? | E34: - | F34: - | G34: N | H34: No reply logged
A35: 02-Sep-2026 | B35: Karishma | C35: 7:35 PM | D35: Wrapping up this stretch - proper little break before close out | E35: 8:30 PM | F35: "Done" | G35: Y
A36: 03-Sep-2026 | B36: Karishma | C36: 12:26 PM | D36: 30 sec for yourself - quick stretch if on calls | E36: - | F36: - | G36: N | H36: Confirmed missed via her 11:28 PM message: "had a very busy day today, couldn't follow the nudges"
A37: 03-Sep-2026 | B37: Karishma | C37: 2:09 PM | D37: Glued to system a while - step away for sometime? | E37: - | F37: - | G37: N | H37: Same
A38: 03-Sep-2026 | B38: Karishma | C38: 4:21 PM | D38: One before focus mode - quick walk or water/coffee | E38: - | F38: - | G38: N | H38: Same
A39: 03-Sep-2026 | B39: Karishma | C39: 5:33 PM | D39: An hour in focus mode - seated stretches if on call | E39: - | F39: - | G39: N | H39: Same
A40: 03-Sep-2026 | B40: Karishma | C40: 7:19 PM | D40: Focused session ending - stand-up, walk, neck stretch | E40: - | F40: - | G40: N | H40: Same
A41: 03-Sep-2026 | B41: Karishma | C41: 8:45 PM | D41: Close to wrapping up day - proper little stretch | E41: 11:28 PM | F41: "I had a very busy day today. Couldn't follow the nudges" | G41: N | H41: Explicit confirmation covering the entire day
A42: 04-Sep-2026 | B42: Karishma | C42: 12:15 PM | D42: Quick stretch/water/tea/coffee before noon mode | E42: 12:34 PM | F42: "Done" | G42: Y
...
